<!DOCTYPE html>
<html lang="en">

<head>
    <meta charset="UTF-8">
    <meta name="viewport" content="width=device-width, initial-scale=1.0">
    <title>Promise</title>
</head>

<body>
    <script src="./js/log.js"></script>
    <script type="text/javascript">
        //  promise
        // const proIns = Promise.resolve(111)
        // const pro = new Promise((resolve, reject) => {
        //     // reject(222)
        //     // return 111  // 没有更改promise的状态，仅返回值，后面不会执行
        //     resolve(111) // 启动promise的状态更改，
        // })
        //     .then(res => {
        //         console.log('第一个' + res)
        //         // 接受状态更改的传递的值，此时promise的状态已经更改了，return可做为下个链式的启动值
        //         // 不返回，后面就是unfined
        //         return proIns
        //     })

        // const promise1 = pro.then(res => {
        //     console.log('第二个' + res)
        // }).then(() => {
        //     console.log(888)
        // })
        // console.log(proIns === pro)

        // const promise2 = promise1.then(res => {
        //     console.log('第三个' + res)
        // }).then(() => {
        //     console.log(999)
        // }).then(() => {
        //     console.log(1000)
        // }).then(res => {
        //     console.log(1001)
        // })

        // Promise拒绝事件  抛出的错误会导致promise被拒绝执行
        // const Pro1 = new Promise((resolve, reject) => {
        //     resolve('promise开始了')
        // })
        // const rejPro1 = Pro1.then(res => {
        //     console.log(res)
        //     throw new Error('抛出错误')
        //     console.log('执行吗')
        // })
        // // .catch(err => {
        // //     console.log(err)
        // // })

        // setTimeout(() => {
        //     rejPro1.catch(11)
        // }, 50)

        // window.onunhandledrejection = function (reason, promise) {
        //     console.log(reason, promise)
        // }



        // window.onrejectionhandled = function (err) {
        //     console.log(err, '======53')
        // }


        // Promise改造
        // const applyAsync = (pro, fun) => pro.then(fun)
        // const composeAsysnc = function (...func) {
        //     console.log(func)
        // }

        // composeAsysnc(test1, test2)
        // function test1() {

        // }

        // function test2() {

        // }


        // promise executor立即执行函数 --报错
        // execPro被创建时就是 已兑现状态，resolve传入的新的Promise会导致其报错，
        // 但内部的new Promise还没有兑现，报错不影响其兑现
        // const execPro = new Promise((resolve, reject) => {
        //     resolve(new Promise((resolveInner) => {
        //         setTimeout(() => {
        //             resolveInner("内部");
        //         }, 100);
        //     }))
        // })
        // execPro.then(console.log)

        // Promise.resolve(11) 相当于
        // new Promise((resove, reject) => {
        //  resolve(11)
        // }).then(res => {
        //    console.log(res)
        // })


        const pro1 = Promise.resolve().then(res => {
            console.log(111)
            return Promise.resolve(222)
        })
        pro1.then(console.log)

        Promise.resolve()
            .then(res => {
                console.log(333)
            }).then(() => {
                console.log(444)
            }).then(() => {
                console.log(555)
            }).then(() => {
                console.log(666)
            })

        // Promise.resolve(Promise.resolve("测试")).then(res => {
        //     console.log(res)
        // })

        // 相当于 pro1是一个promise对象，其最终的状态由Promise.reolve的值决定
        // const pro1 = Promise.resolve(proIns)
        // const pro2 = pro1.then(console.log)
        // console.log(pro1 === proIns)

        // then方法是一个值时，起的作用就是将兑现值传递
        // Promise.resolve(1).then(2).then(console.log) // 1



        // 函数抛出错误或返回一个拒绝的promise，则then返回的promise会被拒绝、
        // 更希望是在catch方法中捕获被拒绝的promise
        // Promise.resolve()
        //     .then(() => {
        //         // 令 .then() 返回一个被拒绝的 promise
        //         throw new Error("Oh no!");
        //     })
        //     .catch((error) => {
        //         console.log(`11 ${error.message}`);
        //     })
        //     .then(
        //         () => {
        //             console.log("不会被调用。");
        //         },
        //         (error) => {
        //             console.error(`onRejected 函数被调用：${error.message}`);
        //         },
        //     )


        // promise对象：
        // Promise是一个构造函数，传入一个立即执行函数executor，此函数拥有两个参数resolve和reject方法，去改变Promise实例对象的状态
        // promise对象拥有三个状态 pending（进行中）  onFulfilled（成功兑现） onRejected（失败兑现）三个状态
        // 由pending--> onFullfiled或者pending --> onRejected状态不可逆，resolve是成功兑现，reject是拒绝
        // 每个实例上面都有then、catch、finally方法
        // then和catch方法会返回一个promise方法，接受一个函数，函数的默认参数为上一个promise的兑现值


        // 构造函数的方法
        // 1. all  接受pormise的集合，集合promise都成功兑现，返回一个promise实例
        // 2. allSettled  接受pormise的集合，集合promise状态都改变（兑现或者拒绝），返回一个promise实例
        // 3. any  接受pormise的集合，集合内任一promise成功兑现，返回一个promise实例
        // 4. race  接受pormise的集合，集合内任一promise状态改变（兑现或者拒绝），返回一个promise实例
        // 5. resolve 返回一个已兑现的promise对象
        // 6. reject  返回一个已拒绝的promise对象
        //

        // promise的核心方法是then方法
        //  then方法是一个异步任务，内部会使用microTask微任务实现，会将函数的返回值使用promise进行封装，返回这个promise
        //  这个promise的状态是由构造函数的resolve或者reject去敲定状态
        //  then内部封装的promise 状态一定会兑现或者拒绝，避免阻塞

        // resolve方法解析规则：
        // 1. Promise.resolve(value)，value为promise，内部判断value.constructor === Promise，是的话就会复用value
        //    不是的话，其实就像是new Promise(resolve => resolve(value))的形式语法糖
        // 2. then方式传入必须是函数（可以是一个没有返回值的函数），内部会用new Promise封装一层，因此then方法可以链式调用
        //    如果传入非函数对象，只会进行透传不处理
        // 3. resolve解析：
        //    1.thenable对象：
        //        具有then方法的对象，then方法会有默认两个参数，类似executor立即函数函数，拥有onFulfilled和onRejected两个方法，onFulfilled会改变状态并且将值返回出去
        //        如果这个onFulfilled方法依旧返回一个thenable对象，那么resolve就会深度扁平化链式处理
        //    2.非thenable对象
        //        返回一个promise已兑现的状态值，兑现值就是resolve传入的值
        //

    </script>
</body>

</html>